Traceback (most recent call last):
  File "/opt/conda/lib/python3.8/site-packages/jupyter_cache/executors/utils.py", line 51, in single_nb_execution
    executenb(
  File "/opt/conda/lib/python3.8/site-packages/nbclient/client.py", line 1085, in execute
    return NotebookClient(nb=nb, resources=resources, km=km, **kwargs).execute()
  File "/opt/conda/lib/python3.8/site-packages/nbclient/util.py", line 84, in wrapped
    return just_run(coro(*args, **kwargs))
  File "/opt/conda/lib/python3.8/site-packages/nbclient/util.py", line 62, in just_run
    return loop.run_until_complete(coro)
  File "/opt/conda/lib/python3.8/asyncio/base_events.py", line 616, in run_until_complete
    return future.result()
  File "/opt/conda/lib/python3.8/site-packages/nbclient/client.py", line 551, in async_execute
    await self.async_execute_cell(
  File "/opt/conda/lib/python3.8/site-packages/nbclient/client.py", line 846, in async_execute_cell
    self._check_raise_for_error(cell, exec_reply)
  File "/opt/conda/lib/python3.8/site-packages/nbclient/client.py", line 748, in _check_raise_for_error
    raise CellExecutionError.from_cell_and_msg(cell, exec_reply_content)
nbclient.exceptions.CellExecutionError: An error occurred while executing the following cell:
------------------
# STEP 1: PREPROCESSING
print("# BATCH INTITIALIZATION")
batch = gbu.calibration.ImageBatchCalibration(
    aruco_dict=aruco.DICT_6X6_250,
    parameters=parameters,
    marker_dimension=marker_dimension,
    output_directory="./_outputs_calibration/",
    camera_matrix=camera_matrix,
    distortion_coefficients=distortion_coefficients,
)

batch.load_image_batch(directory=image_directory)
batch.detect_markers(
    plot_markers=False, enforce=False, meta_filename="metadata.p", protocol=4
)
_ = batch.estimate_pose()
------------------

[0;31m---------------------------------------------------------------------------[0m
[0;31mTypeError[0m                                 Traceback (most recent call last)
[0;32m/tmp/ipykernel_177/341513840.py[0m in [0;36m<module>[0;34m[0m
[1;32m     11[0m [0;34m[0m[0m
[1;32m     12[0m [0mbatch[0m[0;34m.[0m[0mload_image_batch[0m[0;34m([0m[0mdirectory[0m[0;34m=[0m[0mimage_directory[0m[0;34m)[0m[0;34m[0m[0;34m[0m[0m
[0;32m---> 13[0;31m batch.detect_markers(
[0m[1;32m     14[0m     [0mplot_markers[0m[0;34m=[0m[0;32mFalse[0m[0;34m,[0m [0menforce[0m[0;34m=[0m[0;32mFalse[0m[0;34m,[0m [0mmeta_filename[0m[0;34m=[0m[0;34m"metadata.p"[0m[0;34m,[0m [0mprotocol[0m[0;34m=[0m[0;36m4[0m[0;34m[0m[0;34m[0m[0m
[1;32m     15[0m )

[0;31mTypeError[0m: detect_markers() got an unexpected keyword argument 'protocol'
TypeError: detect_markers() got an unexpected keyword argument 'protocol'

