Traceback (most recent call last):
  File "/opt/conda/lib/python3.8/site-packages/jupyter_cache/executors/utils.py", line 51, in single_nb_execution
    executenb(
  File "/opt/conda/lib/python3.8/site-packages/nbclient/client.py", line 1085, in execute
    return NotebookClient(nb=nb, resources=resources, km=km, **kwargs).execute()
  File "/opt/conda/lib/python3.8/site-packages/nbclient/util.py", line 84, in wrapped
    return just_run(coro(*args, **kwargs))
  File "/opt/conda/lib/python3.8/site-packages/nbclient/util.py", line 62, in just_run
    return loop.run_until_complete(coro)
  File "/opt/conda/lib/python3.8/asyncio/base_events.py", line 616, in run_until_complete
    return future.result()
  File "/opt/conda/lib/python3.8/site-packages/nbclient/client.py", line 551, in async_execute
    await self.async_execute_cell(
  File "/opt/conda/lib/python3.8/site-packages/nbclient/client.py", line 846, in async_execute_cell
    self._check_raise_for_error(cell, exec_reply)
  File "/opt/conda/lib/python3.8/site-packages/nbclient/client.py", line 748, in _check_raise_for_error
    raise CellExecutionError.from_cell_and_msg(cell, exec_reply_content)
nbclient.exceptions.CellExecutionError: An error occurred while executing the following cell:
------------------
# SETUP
image_directory = "./_dataset/"

metadata = json.load(open(image_directory + "metadata.json"))
camera_matrix = np.array(metadata["camera_matrix"])
distortion_coefficients = np.array(metadata["distortion_coefficients"])
md = float(metadata["aruco_marker_size"].split()[0])
marker_dimension = {i: md for i in range(1, 250)}
marker_size = 12.4079e-3
marker_dimension = {i: marker_size for i in range(1, 250)}

# Aruco settings
parameters = aruco.DetectorParameters_create()
parameters.cornerRefinementMethod = 3
parameters.cornerRefinementWinSize = 5
parameters.cornerRefinementMaxIterations = 100
------------------

[0;31m---------------------------------------------------------------------------[0m
[0;31mFileNotFoundError[0m                         Traceback (most recent call last)
[0;32m/tmp/ipykernel_178/2363916721.py[0m in [0;36m<module>[0;34m[0m
[1;32m      2[0m [0mimage_directory[0m [0;34m=[0m [0;34m"./_dataset/"[0m[0;34m[0m[0;34m[0m[0m
[1;32m      3[0m [0;34m[0m[0m
[0;32m----> 4[0;31m [0mmetadata[0m [0;34m=[0m [0mjson[0m[0;34m.[0m[0mload[0m[0;34m([0m[0mopen[0m[0;34m([0m[0mimage_directory[0m [0;34m+[0m [0;34m"metadata.json"[0m[0;34m)[0m[0;34m)[0m[0;34m[0m[0;34m[0m[0m
[0m[1;32m      5[0m [0mcamera_matrix[0m [0;34m=[0m [0mnp[0m[0;34m.[0m[0marray[0m[0;34m([0m[0mmetadata[0m[0;34m[[0m[0;34m"camera_matrix"[0m[0;34m][0m[0;34m)[0m[0;34m[0m[0;34m[0m[0m
[1;32m      6[0m [0mdistortion_coefficients[0m [0;34m=[0m [0mnp[0m[0;34m.[0m[0marray[0m[0;34m([0m[0mmetadata[0m[0;34m[[0m[0;34m"distortion_coefficients"[0m[0;34m][0m[0;34m)[0m[0;34m[0m[0;34m[0m[0m

[0;31mFileNotFoundError[0m: [Errno 2] No such file or directory: './_dataset/metadata.json'
FileNotFoundError: [Errno 2] No such file or directory: './_dataset/metadata.json'

