Traceback (most recent call last):
  File "/opt/conda/lib/python3.8/site-packages/jupyter_cache/executors/utils.py", line 51, in single_nb_execution
    executenb(
  File "/opt/conda/lib/python3.8/site-packages/nbclient/client.py", line 1085, in execute
    return NotebookClient(nb=nb, resources=resources, km=km, **kwargs).execute()
  File "/opt/conda/lib/python3.8/site-packages/nbclient/util.py", line 84, in wrapped
    return just_run(coro(*args, **kwargs))
  File "/opt/conda/lib/python3.8/site-packages/nbclient/util.py", line 62, in just_run
    return loop.run_until_complete(coro)
  File "/opt/conda/lib/python3.8/asyncio/base_events.py", line 616, in run_until_complete
    return future.result()
  File "/opt/conda/lib/python3.8/site-packages/nbclient/client.py", line 551, in async_execute
    await self.async_execute_cell(
  File "/opt/conda/lib/python3.8/site-packages/nbclient/client.py", line 846, in async_execute_cell
    self._check_raise_for_error(cell, exec_reply)
  File "/opt/conda/lib/python3.8/site-packages/nbclient/client.py", line 748, in _check_raise_for_error
    raise CellExecutionError.from_cell_and_msg(cell, exec_reply_content)
nbclient.exceptions.CellExecutionError: An error occurred while executing the following cell:
------------------
import trimesh
import numpy as np
from scipy import optimize
import plot_mesh as pltm
import plotly.graph_objects as go
import pandas as pd
import gbu
------------------

[0;31m---------------------------------------------------------------------------[0m
[0;31mModuleNotFoundError[0m                       Traceback (most recent call last)
[0;32m/tmp/ipykernel_176/2042619430.py[0m in [0;36m<module>[0;34m[0m
[1;32m      2[0m [0;32mimport[0m [0mnumpy[0m [0;32mas[0m [0mnp[0m[0;34m[0m[0;34m[0m[0m
[1;32m      3[0m [0;32mfrom[0m [0mscipy[0m [0;32mimport[0m [0moptimize[0m[0;34m[0m[0;34m[0m[0m
[0;32m----> 4[0;31m [0;32mimport[0m [0mplot_mesh[0m [0;32mas[0m [0mpltm[0m[0;34m[0m[0;34m[0m[0m
[0m[1;32m      5[0m [0;32mimport[0m [0mplotly[0m[0;34m.[0m[0mgraph_objects[0m [0;32mas[0m [0mgo[0m[0;34m[0m[0;34m[0m[0m
[1;32m      6[0m [0;32mimport[0m [0mpandas[0m [0;32mas[0m [0mpd[0m[0;34m[0m[0;34m[0m[0m

[0;31mModuleNotFoundError[0m: No module named 'plot_mesh'
ModuleNotFoundError: No module named 'plot_mesh'

